<?xml version="1.0" ?>
<!-- =================================================================================== -->
<!-- |    This document was autogenerated by xacro from catkin_ws/src/mav_arm_force_controlled/src/thirdmodel.urdf.xacro | -->
<!-- |    EDITING THIS FILE BY HAND IS NOT RECOMMENDED                                 | -->
<!-- =================================================================================== -->
<robot name="arm" xmlns:xacro="http://ros.org/wiki/xacro">
  <!-- Material and Colors-->
  <material name="black">
    <color rgba="0.0 0.0 0.0 1.0"/>
  </material>
  <material name="dark_grey">
    <color rgba="0.411764705882 {105/255} 0.411764705882 1.0"/>
  </material>
  <material name="grey">
    <color rgba="0.501960784314 0.501960784314 0.501960784314 1.0"/>
  </material>
  <material name="light_grey">
    <color rgba="0.866666666667 0.866666666667 0.866666666667 1"/>
  </material>
  <material name="white">
    <color rgba="1.0 1.0 1.0 1.0"/>
  </material>
  <material name="red">
    <color rgba="1.0 0.0 0.0 1.0"/>
  </material>
  <!-- The Mass and inertia elements are defined before the link element-->
  <link name="baseplate">
    <visual>
      <geometry>
        <mesh filename="package://mav_arm_force_controlled/meshes/baseplate.stl" scale="0.001 0.001 0.001"/>
      </geometry>
      <origin rpy="0 0 0" xyz="0 0 0"/>
      <!--<origin rpy="0 0 0" xyz="${Baseplate_cog_x} ${Baseplate_cog_y} ${Baseplate_cog_z}"/>-->
      <material name="black"/>
    </visual>
    <inertia>
      <mass value="0.040063354"/>
      <inertia ixx="6.3973e-05" ixy="0" ixz="5.877e-06" iyy="0.000151767" iyz="0" izz="0.000214186"/>
    </inertia>
  </link>
  <joint name="baseplate_to_actuator3" type="fixed">
    <parent link="baseplate"/>
    <child link="actuator3"/>
    <origin rpy="0 0 -1.57076345" xyz="0.048 0 0.022"/>
  </joint>
  <link name="actuator3">
    <visual>
      <geometry>
        <mesh filename="package://mav_arm_force_controlled/meshes/dynamixel.stl" scale="0.001 0.001 0.001"/>
      </geometry>
      <origin rpy="0 0 0" xyz="0 0 0"/>
      <material name="black"/>
    </visual>
    <inertia>
      <origin xyz="dynamixel_cog_x dynamixel_cog_y dynamixel_cog_z"/>
      <mass value="0.126"/>
      <inertia ixx="0" ixy="0" ixz="0" iyy="4.7045e-05" iyz="1.4e-06" izz="0.000115625"/>
    </inertia>
  </link>
  <joint name="actuator3_to_connectingplate" type="continuous">
    <axis rpy="0 0 0" xyz="0 0 1"/>
    <parent link="actuator3"/>
    <child link="connectingbox"/>
    <origin rpy="0 0 3.1415269" xyz="0 0 0.027"/>
    <limit effort="30" velocity="1.0"/>
  </joint>
  <transmission name="actuator3_dynamixel">
    <type>transmission_interface/SimpleTransmission</type>
    <actuator name="$actuator3_dynamixel">
      <mechanicalReduction>1</mechanicalReduction>
    </actuator>
    <joint name="actuator3_to_connectingplate">
      <hardwareInterface>PositionJointInterface</hardwareInterface>
    </joint>
  </transmission>
  <link name="connectingbox">
    <visual>
      <geometry>
        <mesh filename="package://mav_arm_force_controlled/meshes/connecting.stl" scale="0.001 0.001 0.001"/>
      </geometry>
      <origin rpy="0 0 0" xyz="0 0 0"/>
      <material name="black"/>
    </visual>
    <inertia>
      <mass value="0.01"/>
      <inertia ixx="0.001105121" ixy="1.6e-08" ixz="0" iyy="0.001002814" iyz="7.088e-06" izz="0.000170487"/>
    </inertia>
  </link>
  <joint name="connectingbox_to_actuator2" type="fixed">
    <parent link="connectingbox"/>
    <child link="actuator2"/>
    <origin rpy="1.57076345 0 1.57076345" xyz="0.02 0 0.0635"/>
  </joint>
  <link name="actuator2">
    <visual>
      <geometry>
        <mesh filename="package://mav_arm_force_controlled/meshes/hebi.stl" scale="0.001 0.001 0.001"/>
      </geometry>
      <origin rpy="0 0 0" xyz="0 0 0"/>
      <material name="red"/>
    </visual>
    <inertia>
      <mass value="actuator2_mass"/>
      <inertia ixx="0.000186786" ixy="4.1556e-05" ixz="2.73e-07" iyy="0.00043422" iyz="2.9e-07" izz="0.000554524"/>
    </inertia>
  </link>
  <joint name="actuator2_to_clamp3" type="continuous">
    <axis rpy="0 0 0" xyz="0 1 0"/>
    <parent link="actuator2"/>
    <child link="clamp3"/>
    <origin rpy="1.57076345 0 -1.57076345" xyz="0 0 0.01605"/>
    <limit effort="30" velocity="1.0"/>
  </joint>
  <transmission name="actuator2_hebi">
    <type>transmission_interface/SimpleTransmission</type>
    <actuator name="$actuator2_hebi">
      <mechanicalReduction>1</mechanicalReduction>
    </actuator>
    <joint name="actuator2_to_clamp3">
      <hardwareInterface>PositionJointInterface</hardwareInterface>
    </joint>
  </transmission>
  <link name="clamp3">
    <visual>
      <geometry>
        <mesh filename="package://mav_arm_force_controlled/meshes/hebitotube2.stl" scale="0.001 0.001 0.001"/>
      </geometry>
      <origin rpy="0 0 0" xyz="0 0 0"/>
      <material name="black"/>
    </visual>
    <collision>
      <geometry>
        <sphere radius="0.02"/>
      </geometry>
    </collision>
    <inertia>
      <mass value="0.21"/>
      <inertia ixx="0.000524947" ixy="1.7e-08" ixz="-4e-08" iyy="0.000535726" iyz="-9.2479e-05" izz="7.4342e-05"/>
    </inertia>
  </link>
  <joint name="clamp3_to_tube2" type="fixed">
    <parent link="clamp3"/>
    <child link="tube2"/>
    <origin rpy="0 3.1415269 0" xyz="0 0.013 -0.035"/>
  </joint>
  <link name="tube2">
    <visual>
      <geometry>
        <mesh filename="package://mav_arm_force_controlled/meshes/tube2.stl" scale="0.001 0.001 0.001"/>
      </geometry>
      <origin rpy="0 0 0" xyz="0 0 0"/>
      <material name="red"/>
    </visual>
    <inertia>
      <mass value="tube2_mass"/>
      <inertia ixx="0.002039156" ixy="0" ixz="0" iyy="0.002039156" iyz="0" izz="3.457e-06"/>
    </inertia>
  </link>
  <joint name="tube2_to_clamp2" type="fixed">
    <parent link="tube2"/>
    <child link="clamp2"/>
    <origin rpy="1.57076345 0 -3.1415269" xyz="0 -0.018 0.345"/>
  </joint>
  <link name="clamp2">
    <visual>
      <geometry>
        <mesh filename="package://mav_arm_force_controlled/meshes/tube2todynamixel.stl" scale="0.001 0.001 0.001"/>
      </geometry>
      <origin rpy="0 0 0" xyz="0 0 0"/>
      <material name="black"/>
    </visual>
    <inertia>
      <mass value="clamp2_mass"/>
      <inertia ixx="0.00019462" ixy="0" ixz="0" iyy="6.7787e-05" iyz="6.0459e-05" izz="0.000173715"/>
    </inertia>
  </link>
  <joint name="clamp2_to_actuator1" type="fixed">
    <parent link="clamp2"/>
    <child link="actuator1"/>
    <origin rpy="0 3.1415269 0" xyz="0 0.0481 -0.017"/>
  </joint>
  <link name="actuator1">
    <visual>
      <geometry>
        <mesh filename="package://mav_arm_force_controlled/meshes/dynamixel.stl" scale="0.001 0.001 0.001"/>
      </geometry>
      <origin rpy="0 0 0" xyz="0 0 0"/>
      <material name="black"/>
    </visual>
    <inertia>
      <mass value="actuator1_mass"/>
      <inertia ixx="0.000129338" ixy="0" ixz="0" iyy="4.7045e-05" iyz="1.4e-06" izz="0.000115625"/>
    </inertia>
  </link>
  <joint name="actuator1_to_clamp1" type="continuous">
    <axis rpy="0 0 0" xyz="0 0 1"/>
    <parent link="actuator1"/>
    <child link="clamp1"/>
    <origin rpy="0 0 -1.57076345" xyz="0 0 0.0235"/>
    <limit effort="30" velocity="1.0"/>
  </joint>
  <transmission name="actuator1_dynamixel">
    <type>transmission_interface/SimpleTransmission</type>
    <actuator name="$actuator1_dynamixel">
      <mechanicalReduction>1</mechanicalReduction>
    </actuator>
    <joint name="actuator1_to_clamp1">
      <hardwareInterface>PositionJointInterface</hardwareInterface>
    </joint>
  </transmission>
  <link name="clamp1">
    <visual>
      <geometry>
        <mesh filename="package://mav_arm_force_controlled/meshes/dynamixeltotube1.stl" scale="0.001 0.001 0.001"/>
      </geometry>
      <origin rpy="0 0 0" xyz="0 0 0"/>
      <material name="red"/>
    </visual>
    <inertia>
      <mass value="clamp1_mass"/>
      <inertia ixx="4.5773e-05" ixy="-3e-08" ixz="2.2588e-05" iyy="7.9456e-05" iyz="1e-09" izz="7.801e-05"/>
    </inertia>
  </link>
  <joint name="clamp1_to_tube1" type="fixed">
    <parent link="clamp1"/>
    <child link="tube1"/>
    <origin rpy="0 1.57076345 0" xyz="0.015 0 0.022"/>
  </joint>
  <link name="tube1">
    <visual>
      <geometry>
        <mesh filename="package://mav_arm_force_controlled/meshes/tube1.stl" scale="0.001 0.001 0.001"/>
      </geometry>
      <origin rpy="0 0 0" xyz="0 0 0"/>
      <material name="black"/>
    </visual>
    <inertia>
      <mass value="tube1_mass"/>
      <inertia ixx="0.002443367" ixy="0" ixz="0" iyy="0.002443367" iyz="0" izz="9.29e-07"/>
    </inertia>
  </link>
  <joint name="tube1_to_tip" type="fixed">
    <parent link="tube1"/>
    <child link="tip"/>
    <origin rpy="0 0 0" xyz="0 0 0.6"/>
  </joint>
  <link name="tip">
    <visual>
      <geometry>
        <mesh filename="package://mav_arm_force_controlled/meshes/tip.stl" scale="0.001 0.001 0.001"/>
      </geometry>
      <origin rpy="0 0 0" xyz="0 0 0"/>
      <material name="white"/>
    </visual>
    <inertia>
      <mass value="tip_mass"/>
      <inertia ixx="7.58e-07" ixy="0" ixz="0" iyy="7.58e-07" iyz="0" izz="8e-07"/>
    </inertia>
  </link>
  <gazebo>
    <plugin filename="libgazebo_ros_control.so" name="gazebo_ros_control">
      <robotNamespace>/</robotNamespace>
    </plugin>
  </gazebo>
</robot>
