<?xml version="1.0"?>
<robot name="arm">

  <material name="black">
    <color rgba="0 0 0 1"/>
  </material>
  <material name="light_grey">
    <color rgba="0 0 0 0.2"/>
  </material>
  <material name="grey">
    <color rgba="0 0 0 0.5"/>
  </material>
  <material name="dark_grey">
    <color rgba="0 0 0 0.7"/>
  </material>
  <material name="white">
    <color rgba="1 1 1 1"/>
  </material>


  <link name="base_plate">
    <visual>
      <geometry>
        <box size="0.1 0.1 0.001"/>
      </geometry>
      <origin rpy="0 0 0" xyz="0 0 0.0005"/>
      <material name="dark_grey"/>
    </visual>
    <collision>
      <geometry>
        <box size="0.1 0.1 0.001"/>
      </geometry>
    </collision>
    <inertia>
      <mass value="0.1"/>
      <inertia ixx="0.0000420833" ixy="0" ixz="0" iyy="0.00008333" iyz="0" izz="0.0000420833" />
    </inertia>
  </link>

  <joint name="baseplate_to_actuator3" type="fixed">
    <parent link="base_plate"/>
    <child link="actuator3"/>
    <origin rpy="0 0 0" xyz="0 0 0.001"/>
  </joint>

  <link name="actuator3">
    <visual>
      <origin rpy="0 0 0" xyz="0 0 0.0205"/>
      <geometry>
        <box size="0.04 0.061 0.041"/>
      </geometry>
      <material name="white"/>
    </visual>
    <collision>
      <geometry>
        <box size="0.04 0.061 0.041"/>
      </geometry>
    </collision>
    <inertia>
      <mass value="0.22"/>
      <inertia ixx="0.00003691125" ixy="0" ixz="0" iyy="0.00005986125" iyz="0" izz="0.0000607725" />
    </inertia>
  </link>

  <joint name="actuator3_to_connectingplate" type="continuous">
    <axis rpy="0 0 0" xyz="0 0 1"/>
    <parent link="actuator3"/>
    <child link="connectingbox"/>
    <origin xyz="0 0.01755 0.041"/>
  </joint>


  <link name="connectingbox">
    <visual>
      <geometry>
        <box size="0.043 0.06 0.0995"/>
      </geometry>
      <origin rpy="0 0 0" xyz="0 0 0.04975"/>
      <material name="white"/>
    </visual>
    <collision>
      <geometry>
        <box size="0.043 0.06 0.0995"/>
      </geometry>
    </collision>
    <inertia>
      <mass value="0.01"/>
      <inertia ixx="0.0012" ixy="0" ixz="0" iyy="0" iyz="0" izz="0.0012" />
    </inertia>
  </link>


  <joint name="connectingbox_to_actuator2" type="fixed">
    <parent link="connectingbox"/>
    <child link="actuator2"/>
    <origin xyz="-0.0215 0 0.06"/>
  </joint>

  <link name="actuator2">
    <visual>
      <geometry>
        <box size="0.031 0.11 0.073"/>
      </geometry>
      <origin rpy="0 0 0" xyz="-0.0155 -0.025 0"/>
      <material name="white"/>
    </visual>
    <collision>
      <geometry>
        <box size="0.031 0.11 0.073"/>
      </geometry>
    </collision>
    <inertia>
      <mass value="0.01"/>
      <inertia ixx="0.0012" ixy="0" ixz="0" iyy="0" iyz="0" izz="0.0012" />
    </inertia>
  </link>

  <joint name="actuator2_to_tube2" type="continuous">
    <axis rpy="0 0 0" xyz="1 0 0"/>
    <parent link="actuator2"/>
    <child link="tube2"/>
    <origin xyz="-0.031 0 0"/>
  </joint>


  <link name="tube2">
    <visual>
      <geometry>
        <cylinder length="0.6" radius="0.01"/>
      </geometry>
      <origin rpy="1.570796 0 0" xyz="-0.01 0.3 0"/>
      <material name="light_grey"/>
    </visual>
    <collision>
      <geometry>
        <cylinder length="0.6" radius="0.01"/>
      </geometry>
    </collision>
    <inertia>
      <mass value="0.01"/>
      <inertia ixx="0.0012" ixy="0" ixz="0" iyy="0" iyz="0" izz="0.0012" />
    </inertia>
  </link>

    <joint name="tube2_to_actuator1" type="fixed">
      <parent link="tube2"/>
      <child link="actuator1"/>
      <origin rpy="0 1.5707963 0" xyz="0 0.6 0"/>
    </joint>


  <link name="actuator1">
    <visual>
      <geometry>
        <box size="0.04 0.061 0.041"/>
      </geometry>
      <origin rpy="0 0 0" xyz="0 -0.0305 0.0205"/>
      <material name="black"/>
    </visual>
    <collision>
      <geometry>
        <box size="0.04 0.061 0.041"/>
      </geometry>
    </collision>
    <inertia>
      <mass value="0.22"/>
      <inertia ixx="0.00003691125" ixy="0" ixz="0" iyy="0.00005986125" iyz="0" izz="0.0000607725" />
    </inertia>
  </link>


  <joint name="actuator1_to_tube1" type="continuous">
    <axis rpy="0 0 0" xyz="0 0 1"/>
    <parent link="actuator1"/>
    <child link="tube1"/>
    <origin xyz="0 -0.013 0.041"/>
  </joint>


    <link name="tube1">
      <visual>
        <geometry>
          <cylinder length="0.4" radius="0.007"/>
        </geometry>
        <origin rpy="1.570796 0 0" xyz="0 0.2 0.007"/>
        <material name="light_grey"/>
      </visual>
      <collision>
        <geometry>
          <cylinder length="0.4" radius="0.007"/>
        </geometry>
      </collision>
      <inertia>
        <mass value="0.01"/>
        <inertia ixx="0.0012" ixy="0" ixz="0" iyy="0" iyz="0" izz="0.0012" />
      </inertia>
    </link>

    <joint name="tube1_to_tip" type="fixed">
      <parent link="tube1"/>
      <child link="tip"/>
      <origin xyz="0 0.4 0.007"/>
    </joint>

    <link name="tip">
      <visual>
        <geometry>
          <sphere radius="0.007"/>
        </geometry>
        <origin rpy="0 0 0" xyz="0 0 0"/>
        <material name="white"/>
      </visual>
      <collision>
        <geometry>
          <sphere radius="0.014"/>
        </geometry>
      </collision>
      <inertia>
        <mass value="0.01"/>
        <inertia ixx="0.00028" ixy="0" ixz="0" iyy="0.00028" iyz="0" izz="0.00028" />
      </inertia>
    </link>
</robot>
