<?xml version="1.0"?>
<robot name="arm" xmlns:xacro="http://ros.org/wiki/xacro">



    <!-- Import all Gazebo-customization elements, including Gazebo colors -->
    <xacro:include filename="$(find mav_arm_force_controlled)/src/arm_gazebo_materials.gazebo" />

    <!-- Import Rviz colors -->
    <xacro:include filename="$(find mav_arm_force_controlled)/src/arm_rviz_materials.xacro" />

    <!-- General Variables-->
    <xacro:property name="pi" value="3.1415926535897931" />

    <!-- Mesh files of exact geometry-->
    <xacro:property name="mesh_file_baseplate" value="package://mav_arm_force_controlled/meshes/geometry_2.0/voliro_arm_base_dynamixel_balanced.stl" />
    <xacro:property name="mesh_file_dyamixel" value="package://mav_arm_force_controlled/meshes/geometry_2.0/voliro_arm_dynamixel.stl" />
    <xacro:property name="mesh_file_dyamixel_to_hebi" value="package://mav_arm_force_controlled/meshes/geometry_2.0/voliro_arm_dynamixel_to_hebi.stl" />
    <xacro:property name="mesh_file_hebi" value="package://mav_arm_force_controlled/meshes/geometry_2.0/voliro_arm_hebi.stl" />
    <xacro:property name="mesh_file_clamp2" value="package://mav_arm_force_controlled/meshes/geometry_2.0/voliro_arm_clamp2.stl" />
    <xacro:property name="mesh_file_tube2" value="package://mav_arm_force_controlled/meshes/geometry_2.0/voliro_arm_tube2.stl" />
    <xacro:property name="mesh_file_tube_adapter" value="package://mav_arm_force_controlled/meshes/geometry_2.0/voliro_arm_tube_adapter.stl" />
    <xacro:property name="mesh_file_actuator1" value="package://mav_arm_force_controlled/meshes/geometry_2.0/voliro_arm_dynamixel.stl" />
    <xacro:property name="mesh_file_clamp1" value="package://mav_arm_force_controlled/meshes/geometry_2.0/voliro_arm_clamp1.stl" />
    <xacro:property name="mesh_file_tube1" value="package://mav_arm_force_controlled/meshes/geometry_2.0/voliro_arm_tube1.stl" />
    <xacro:property name="mesh_file_tip" value="package://mav_arm_force_controlled/meshes/geometry_2.0/voliro_arm_tip.stl" />


    <!-- Mesh files of simplified geometry for collision checking-->
    <xacro:property name="s_mesh_file_baseplate" value="package://mav_arm_force_controlled/meshes/simplified_geometry_2.0/voliro_arm_base_dynamixel_balanced.stl" />
    <xacro:property name="s_mesh_file_dyamixel" value="package://mav_arm_force_controlled/meshes/simplified_geometry_2.0/voliro_arm_dynamixel.stl" />
    <xacro:property name="s_mesh_file_dyamixel_to_hebi" value="package://mav_arm_force_controlled/meshes/simplified_geometry_2.0/voliro_arm_dynamixel_to_hebi.stl" />
    <xacro:property name="s_mesh_file_hebi" value="package://mav_arm_force_controlled/meshes/simplified_geometry_2.0/voliro_arm_hebi.stl" />
    <xacro:property name="s_mesh_file_clamp2" value="package://mav_arm_force_controlled/meshes/simplified_geometry_2.0/voliro_arm_clamp2.stl" />
    <xacro:property name="s_mesh_file_tube2" value="package://mav_arm_force_controlled/meshes/simplified_geometry_2.0/voliro_arm_tube2.stl" />
    <xacro:property name="s_mesh_file_tube_adapter" value="package://mav_arm_force_controlled/meshes/simplified_geometry_2.0/voliro_arm_tube_adapter.stl" />
    <xacro:property name="s_mesh_file_actuator1" value="package://mav_arm_force_controlled/meshes/simplified_geometry_2.0/voliro_arm_dynamixel.stl" />
    <xacro:property name="s_mesh_file_clamp1" value="package://mav_arm_force_controlled/meshes/simplified_geometry_2.0/voliro_arm_clamp1.stl" />
    <xacro:property name="s_mesh_file_tube1" value="package://mav_arm_force_controlled/meshes/simplified_geometry_2.0/voliro_arm_tube1.stl" />
    <xacro:property name="s_mesh_file_tip" value="package://mav_arm_force_controlled/meshes/simplified_geometry_2.0/voliro_arm_tip.stl" />






    <!-- Mesh files are in mm. All mesh files are scaled by the factor 1000-->
    <xacro:property name="mesh_scale" value="0.001" />

    <!-- Unit conversion for inertia from kg*mm² to kg*m² -->
    <xacro:property name="uc_inertia" value="0.000001" />

    <!-- The mass and inertia elements are defined before the link element -->
    <xacro:property name="baseplate_mass" value="0.034534697" />

    <xacro:property name="baseplate_cog_x" value="-0.0155840153" />
    <xacro:property name="baseplate_cog_y" value="0.03245573125" />
    <xacro:property name="baseplate_cog_z" value="0.01488134446" />

    <xacro:property name="baseplate_ixx" value="${60.4589042*uc_inertia}" />
    <xacro:property name="baseplate_ixy" value="${-23.91373491*uc_inertia}" />
    <xacro:property name="baseplate_ixz" value="${-9.415308277*uc_inertia}" />
    <xacro:property name="baseplate_iyy" value="${32.25701807*uc_inertia}" />
    <xacro:property name="baseplate_iyz" value="${17.84460765*uc_inertia}" />
    <xacro:property name="baseplate_izz" value="${75.37700913*uc_inertia}" />


  <link name="world"/>

  <joint name="fixed" type="fixed">
    <parent link="world"/>
    <child link="baseplate"/>
    <origin xyz="0.03244 0.0481 0.02" rpy="${pi} 0 0" />
  </joint>

  <link name="baseplate">
    <visual>
      <geometry>
          <mesh filename="${mesh_file_baseplate}"
                scale="${mesh_scale} ${mesh_scale} ${mesh_scale}"/>
        </geometry>
      <origin rpy="0 0 0" xyz="0 0 0"/>
    </visual>
    <collision>
      <geometry>
        <mesh filename="${s_mesh_file_baseplate}"
              scale="${mesh_scale} ${mesh_scale} ${mesh_scale}"/>
        </geometry>
      <origin rpy="0 0 0" xyz="0 0 0"/>
    </collision>
    <inertial>
      <mass value="${baseplate_mass}"/>
      <inertia ixx="${baseplate_ixx}" ixy="${baseplate_ixy}" ixz="${baseplate_ixz}" iyy="${baseplate_iyy}" iyz="${baseplate_iyz}" izz="${baseplate_izz}" />
    </inertial>
  </link>



  <joint name="baseplate_to_actuator3" type="fixed">
    <parent link="baseplate"/>
    <child link="actuator3"/>
    <origin rpy="${pi} 0 ${pi}" xyz="0 ${0.0425+0.0056} -0.017"/>
  </joint>



  <xacro:property name="dynamixel_mass" value="0.135" />

  <xacro:property name="dynamixel_cog_x" value="0.000000008" />
  <xacro:property name="dynamixel_cog_y" value="0.01519089" />
  <xacro:property name="dynamixel_cog_z" value="0.000362847" />

  <xacro:property name="dynamixel_ixx" value="0.000129338" />
  <xacro:property name="dynamixel_ixy" value="0" />
  <xacro:property name="dynamixel_ixz" value="0" />
  <xacro:property name="dynamixel_iyy" value="0.000047045" />
  <xacro:property name="dynamixel_iyz" value="0.0000014" />
  <xacro:property name="dynamixel_izz" value="0.000115625" />


  <link name="actuator3">
    <visual>
      <geometry>
          <mesh filename="${mesh_file_dyamixel}"
                scale="${mesh_scale} ${mesh_scale} ${mesh_scale}"/>
        </geometry>
        <origin rpy="0 0 0" xyz="0 0 0"/>
        <material name="black"/>
    </visual>
    <collision>
      <geometry>s
        <mesh filename="${s_mesh_file_dyamixel}"
              scale="${mesh_scale} ${mesh_scale} ${mesh_scale}"/>
        </geometry>
      <origin rpy="0 0 0" xyz="0 0 0"/>
    </collision>
    <inertial>
      <mass value="${dynamixel_mass}"/>
      <inertia ixx="${dynamixel_ixy}" ixy="${dynamixel_ixy}" ixz="${dynamixel_ixz}" iyy="${dynamixel_iyy}" iyz="${dynamixel_iyz}" izz="${dynamixel_izz}" />
    </inertial>
  </link>




  <joint name="actuator_to_hebi" type="revolute">
    <axis rpy="0 0 0" xyz="0 0 1"/>
    <parent link="actuator3"/>
    <child link="dynamixel_to_hebi"/>
    <origin rpy="0 0 ${pi/2}" xyz="0 0 ${0.0235+0.012}"/>
    <!--<limit effort="100" velocity="10"/>-->
    <limit effort="5" lower="${-pi/2}" upper="${pi/2}" velocity="1" />
  </joint>


  <transmission name="actuator3_dynamixel_trans">
    <type>transmission_interface/SimpleTransmission</type>
    <joint name="actuator_to_hebi">
      <hardwareInterface>hardware_interface/EffortJointInterface</hardwareInterface>
    </joint>
    <actuator name="actuator3_dynamixel_motor">
      <hardwareInterface>hardware_interface/EffortJointInterface</hardwareInterface>
      <mechanicalReduction>1</mechanicalReduction>
    </actuator>
  </transmission>

  <xacro:property name="bearing_mass" value="0.123" />

  <xacro:property name="bearing_cog_x" value="0.008737243596" />
  <xacro:property name="bearing_cog_y" value="0.00095854858" />
  <xacro:property name="bearing_cog_z" value="-0.01965454186" />

  <xacro:property name="bearing_ixx" value="${139.5553029*uc_inertia}" />
  <xacro:property name="bearing_ixy" value="${0.414376963*uc_inertia}" />
  <xacro:property name="bearing_ixz" value="${-31.92210758*uc_inertia}" />
  <xacro:property name="bearing_iyy" value="${162.416508*uc_inertia}" />
  <xacro:property name="bearing_iyz" value="${-0.344517543*uc_inertia}" />
  <xacro:property name="bearing_izz" value="${80.76641832*uc_inertia}" />


  <link name="dynamixel_to_hebi">
    <visual>
      <geometry>
        <mesh filename="${mesh_file_dyamixel_to_hebi}"
              scale="${mesh_scale} ${mesh_scale} ${mesh_scale}"/>
      </geometry>
      <origin rpy="0 0 0" xyz="0 0 0"/>
      <material name="black"/>
    </visual>
    <collision>
      <geometry>
        <mesh filename="${s_mesh_file_dyamixel_to_hebi}"
              scale="${mesh_scale} ${mesh_scale} ${mesh_scale}"/>
        </geometry>
      <origin rpy="0 0 0" xyz="0 0 0"/>
    </collision>
    <inertial>
      <mass value="${bearing_mass}"/>
      <inertia ixx="${bearing_ixx}" ixy="${bearing_ixy}" ixz="${bearing_ixz}" iyy="${bearing_iyy}" iyz="${bearing_iyz}" izz="${bearing_izz}" />
    </inertial>
  </link>




  <joint name="bearing_to_actuator2" type="fixed">
    <parent link="dynamixel_to_hebi"/>
    <child link="actuator2"/>
    <origin rpy="${pi/2} ${0} ${pi/2}"  xyz="${0.038+0.015} ${0} ${-0.029}"/>
  </joint>

  <xacro:property name="actuator2_mass" value="0.34" />

  <xacro:property name="actuator2_cog_x" value="0.000000171" />
  <xacro:property name="actuator2_cog_y" value="0.000278026" />
  <xacro:property name="actuator2_cog_z" value="0.038471524" />

  <xacro:property name="actuator2_ixx" value="0.000186786" />
  <xacro:property name="actuator2_ixy" value="0.000041556" />
  <xacro:property name="actuator2_ixz" value="0.000000273" />
  <xacro:property name="actuator2_iyy" value="0.00043422" />
  <xacro:property name="actuator2_iyz" value="0.00000029" />
  <xacro:property name="actuator2_izz" value="0.000554524" />

  <link name="actuator2">
    <visual>
      <geometry>
        <mesh filename="${mesh_file_hebi}"
              scale="${mesh_scale} ${mesh_scale} ${mesh_scale}"/>
      </geometry>
      <origin rpy="0 0 0" xyz="0 0 0"/>
      <material name="red"/>
    </visual>
    <collision>
      <geometry>
        <mesh filename="${s_mesh_file_hebi}"
              scale="${mesh_scale} ${mesh_scale} ${mesh_scale}"/>
        </geometry>
      <origin rpy="0 0 0" xyz="0 0 0"/>
    </collision>
    <inertial>
      <mass value="${actuator2_mass}"/>
      <inertia ixx="${actuator2_ixx}" ixy="${actuator2_ixy}" ixz="${actuator2_ixz}" iyy="${actuator2_iyy}" iyz="${actuator2_iyz}" izz="${actuator2_izz}" />
    </inertial>
  </link>


  <joint name="actuator2_to_clamp2" type="continuous">
    <axis rpy="0 0 0" xyz="0 -1 0"/>
    <parent link="actuator2"/>
    <child link="clamp2"/>
    <origin rpy="${pi/2} ${0} ${0}" xyz="${0} ${0} ${0.01605}"/>
    <limit effort="5" velocity="1" />
    <!--<limit effort="100" lower="${-2*pi}" upper="${2*pi}" velocity="10" />-->
  </joint>


  <transmission name="actuator2_hebi_trans">
    <type>transmission_interface/SimpleTransmission</type>
    <actuator name="$actuator2_hebi_motor">
      <mechanicalReduction>1</mechanicalReduction>
    </actuator>
    <joint name="actuator2_to_clamp2">
      <hardwareInterface>hardware_interface/EffortJointInterface</hardwareInterface>
    </joint>
  </transmission>


  <xacro:property name="clamp2_mass" value="0.029" />

  <xacro:property name="clamp2_cog_x" value="0.00000000019" />
  <xacro:property name="clamp2_cog_y" value="0.008.118243555" />
  <xacro:property name="clamp2_cog_z" value="-0.01350332735" />

  <xacro:property name="clamp2_ixx" value="${21.61924342*uc_inertia}" />
  <xacro:property name="clamp2_ixy" value="${-0.000002107*uc_inertia}" />
  <xacro:property name="clamp2_ixz" value="${0.000000228*uc_inertia}" />
  <xacro:property name="clamp2_iyy" value="${23.46303475*uc_inertia}" />
  <xacro:property name="clamp2_iyz" value="${-4.826007788*uc_inertia}" />
  <xacro:property name="clamp2_izz" value="${7.990509672*uc_inertia}" />

  <link name="clamp2">
    <visual>
      <geometry>
        <mesh filename="${mesh_file_clamp2}"
              scale="${mesh_scale} ${mesh_scale} ${mesh_scale}"/>
      </geometry>
      <origin rpy="0 0 0" xyz="0 0 0"/>
      <material name="black"/>
    </visual>
    <collision>
      <geometry>
        <mesh filename="${s_mesh_file_clamp2}"
              scale="${mesh_scale} ${mesh_scale} ${mesh_scale}"/>
        </geometry>
      <origin rpy="0 0 0" xyz="0 0 0"/>
    </collision>
    <inertial>
      <mass value="${clamp2_mass}"/>
      <inertia ixx="${clamp2_ixx}" ixy="${clamp2_ixy}" ixz="${clamp2_ixz}" iyy="${clamp2_iyy}" iyz="${clamp2_iyz}" izz="${clamp2_izz}" />
    </inertial>
  </link>



  <joint name="clamp2_to_tube2" type="fixed">
    <parent link="clamp2"/>
    <child link="tube2"/>
    <origin rpy="0 ${pi} 0" xyz="${0} ${0.012} ${-0.02}"/>
  </joint>

  <xacro:property name="tube2_mass" value="0.038201767" />

  <xacro:property name="tube2_cog_x" value="0" />
  <xacro:property name="tube2_cog_y" value="0" />
  <xacro:property name="tube2_cog_z" value="0.2" />

  <xacro:property name="tube2_ixx" value="0.002039156" />
  <xacro:property name="tube2_ixy" value="0" />
  <xacro:property name="tube2_ixz" value="0" />
  <xacro:property name="tube2_iyy" value="0.002039156" />
  <xacro:property name="tube2_iyz" value="0" />
  <xacro:property name="tube2_izz" value="0.000003457" />

  <link name="tube2">
    <visual>
      <geometry>
        <mesh filename="${mesh_file_tube2}"
              scale="${mesh_scale} ${mesh_scale} ${mesh_scale}"/>
      </geometry>
      <origin rpy="0 0 0" xyz="0 0 0"/>
      <material name="red"/>
    </visual>
    <collision>
      <geometry>
        <mesh filename="${s_mesh_file_tube2}"
              scale="${mesh_scale} ${mesh_scale} ${mesh_scale}"/>
        </geometry>
      <origin rpy="0 0 0" xyz="0 0 0"/>
    </collision>
    <inertial>
      <mass value="${tube2_mass}"/>
      <inertia ixx="${tube2_ixx}" ixy="${tube2_ixy}" ixz="${tube2_ixz}" iyy="${tube2_iyy}" iyz="${tube2_iyz}" izz="${tube2_izz}" />
    </inertial>
  </link>



    <joint name="tube2_to_adapter" type="fixed">
      <parent link="tube2"/>
      <child link="tube_adapter"/>
      <origin rpy="${pi/2} 0 ${-pi}" xyz="${0} ${-0.02} ${0.4-0.0056}"/>
    </joint>

    <xacro:property name="clamp2_mass" value="0.02919169" />

    <xacro:property name="clamp2_cog_x" value="-0.000051031" />
    <xacro:property name="clamp2_cog_y" value="-5.987489264" />
    <xacro:property name="clamp2_cog_z" value="20" />

    <xacro:property name="clamp2_ixx" value="${21.61924342*uc_inertia}" />
    <xacro:property name="clamp2_ixy" value="${-0.000002107*uc_inertia}" />
    <xacro:property name="clamp2_ixz" value="${0.000000228*uc_inertia}" />
    <xacro:property name="clamp2_iyy" value="${23.46303475*uc_inertia}" />
    <xacro:property name="clamp2_iyz" value="${-4.826007788*uc_inertia}" />
    <xacro:property name="clamp2_izz" value="${7.990509672*uc_inertia}" />

    <link name="tube_adapter">
      <visual>
        <geometry>
          <mesh filename="${mesh_file_tube_adapter}"
                scale="${mesh_scale} ${mesh_scale} ${mesh_scale}"/>
        </geometry>
        <origin rpy="0 0 0" xyz="0 0 0"/>
        <material name="black"/>
      </visual>
      <collision>
        <geometry>
          <mesh filename="${s_mesh_file_tube_adapter}"
                scale="${mesh_scale} ${mesh_scale} ${mesh_scale}"/>
          </geometry>
        <origin rpy="0 0 0" xyz="0 0 0"/>
      </collision>
      <inertial>
        <mass value="${clamp2_mass}"/>
        <inertia ixx="${clamp2_ixx}" ixy="${clamp2_ixy}" ixz="${clamp2_ixz}" iyy="${clamp2_iyy}" iyz="${clamp2_iyz}" izz="${clamp2_izz}" />
      </inertial>
    </link>



      <joint name="clamp2_to_actuator1" type="fixed">
        <parent link="tube_adapter"/>
        <child link="actuator1"/>
        <origin rpy="0 ${pi} 0" xyz="${0} ${0.0425+0.0056} ${0.017+0.003}"/>
      </joint>

      <xacro:property name="actuator1_mass" value="0.135" />

      <xacro:property name="actuator1_cog_x" value="0.000000008" />
      <xacro:property name="actuator1_cog_y" value="-0.01519089" />
      <xacro:property name="actuator1_cog_z" value="0.000362847" />

      <xacro:property name="actuator1_ixx" value="0.000129338" />
      <xacro:property name="actuator1_ixy" value="0" />
      <xacro:property name="actuator1_ixz" value="0" />
      <xacro:property name="actuator1_iyy" value="0.000047045" />
      <xacro:property name="actuator1_iyz" value="0.0000014" />
      <xacro:property name="actuator1_izz" value="0.000115625" />

    <link name="actuator1">
      <visual>
        <geometry>
            <mesh filename="${mesh_file_actuator1}"
              scale="${mesh_scale} ${mesh_scale} ${mesh_scale}"/>
          </geometry>
        <origin rpy="0 0 0" xyz="0 0 0"/>
        <material name="black"/>
      </visual>
      <collision>
        <geometry>
          <mesh filename="${s_mesh_file_actuator1}"
            scale="${mesh_scale} ${mesh_scale} ${mesh_scale}"/>
          </geometry>
        <origin rpy="0 0 0" xyz="0 0 0"/>
      </collision>
      <inertial>
        <mass value="${actuator1_mass}"/>
        <inertia ixx="${actuator1_ixx}" ixy="${actuator1_ixy}" ixz="${actuator1_ixz}" iyy="${actuator1_iyy}" iyz="${actuator1_iyz}" izz="${actuator1_izz}" />
      </inertial>
    </link>



  <joint name="actuator1_to_clamp1" type="continuous">
    <axis rpy="0 0 0" xyz="0 0 1"/>
    <parent link="actuator1"/>
    <child link="clamp1"/>
    <origin rpy="${0} ${0} ${0}" xyz="${0} ${0} ${0.0235}"/>
    <limit effort="5" velocity="1" />
    <!--<limit effort="100" lower="${-2*pi}" upper="${2*pi}" velocity="10" />-->
  </joint>

  <transmission name="actuator1_dynamixel_trans">
    <type>transmission_interface/SimpleTransmission</type>
    <joint name="actuator1_to_clamp1">
      <hardwareInterface>hardware_interface/EffortJointInterface</hardwareInterface>
    </joint>
    <actuator name="actuator1_dynamixel">
      <hardwareInterface>hardware_interface/EffortJointInterface</hardwareInterface>
      <mechanicalReduction>1</mechanicalReduction>
    </actuator>
  </transmission>




  <xacro:property name="clamp1_mass" value="0.084238767" />

  <xacro:property name="clamp1_cog_x" value="-0.000000709384" />
  <xacro:property name="clamp1_cog_y" value="0.003831382911" />
  <xacro:property name="clamp1_cog_z" value="0.007840028704" />

  <xacro:property name="clamp1_ixx" value="${35.98639204*uc_inertia}" />
  <xacro:property name="clamp1_ixy" value="${-0.036707373*uc_inertia}" />
  <xacro:property name="clamp1_ixz" value="${-0.00032096*uc_inertia}" />
  <xacro:property name="clamp1_iyy" value="${26.23411723*uc_inertia}" />
  <xacro:property name="clamp1_iyz" value="${7.078559572*uc_inertia}" />
  <xacro:property name="clamp1_izz" value="${43.83528986*uc_inertia}" />


  <link name="clamp1">
    <visual>
      <geometry>
        <mesh filename="${mesh_file_clamp1}"
          scale="${mesh_scale} ${mesh_scale} ${mesh_scale}"/>
      </geometry>
      <origin rpy="0 0 0" xyz="0 0 0"/>
      <material name="red"/>
    </visual>
    <collision>
      <geometry>
        <mesh filename="${s_mesh_file_clamp1}"
          scale="${mesh_scale} ${mesh_scale} ${mesh_scale}"/>
        </geometry>
      <origin rpy="0 0 0" xyz="0 0 0"/>
    </collision>
    <inertial>
      <mass value="${clamp1_mass}"/>
      <inertia ixx="${clamp1_ixx}" ixy="${clamp1_ixy}" ixz="${clamp1_ixz}" iyy="${clamp1_iyy}" iyz="${clamp1_iyz}" izz="${clamp1_izz}" />
    </inertial>
  </link>




  <joint name="clamp1_to_tube1" type="fixed">
    <parent link="clamp1"/>
    <child link="tube1"/>
    <origin rpy="${0} ${pi/2} ${pi/2}" xyz="${0} ${0.016} ${0.022}"/>
  </joint>

  <xacro:property name="tube1_mass" value="0.039207076" />

  <xacro:property name="tube1_cog_x" value="0" />
  <xacro:property name="tube1_cog_y" value="0" />
  <xacro:property name="tube1_cog_z" value="0.3" />

  <xacro:property name="tube1_ixx" value="${uc_inertia*4705.682308}" />
  <xacro:property name="tube1_ixy" value="0" />
  <xacro:property name="tube1_ixz" value="0" />
  <xacro:property name="tube1_iyy" value="${uc_inertia*4705.682308}" />
  <xacro:property name="tube1_iyz" value="0" />
  <xacro:property name="tube1_izz" value="${uc_inertia*1.666300743}" />

    <link name="tube1">
      <visual>
        <geometry>
          <mesh filename="${mesh_file_tube1}"
            scale="${mesh_scale} ${mesh_scale} ${mesh_scale}"/>
        </geometry>
        <origin rpy="0 0 0" xyz="0 0 0"/>
      </visual>
      <collision>
        <geometry>
          <mesh filename="${s_mesh_file_tube1}"
            scale="${mesh_scale} ${mesh_scale} ${mesh_scale}"/>
          </geometry>
        <origin rpy="0 0 0" xyz="0 0 0"/>
      </collision>
      <inertial>
        <mass value="${tube1_mass}"/>
        <inertia ixx="${tube1_ixx}" ixy="${tube1_ixy}" ixz="${tube1_ixz}" iyy="${tube1_iyy}" iyz="${tube1_iyz}" izz="${tube1_izz}" />
      </inertial>
    </link>




    <joint name="tube1_to_tip" type="fixed">
      <parent link="tube1"/>
      <child link="tip"/>
      <origin rpy="${0} ${0} ${0}" xyz="${0} ${0} ${0.6}"/>
    </joint>

    <xacro:property name="tip_mass" value="0.001540637" />

    <xacro:property name="tip_cog_x" value="0" />
    <xacro:property name="tip_cog_y" value="0" />
    <xacro:property name="tip_cog_z" value="0.000367659054" />

    <xacro:property name="tip_ixx" value="${0.028658362*uc_inertia}" />
    <xacro:property name="tip_ixy" value="${0*uc_inertia}" />
    <xacro:property name="tip_ixz" value="${0*uc_inertia}" />
    <xacro:property name="tip_iyy" value="${0.028658362*uc_inertia}" />
    <xacro:property name="tip_iyz" value="${0*uc_inertia}" />
    <xacro:property name="tip_izz" value="${0.029110752*uc_inertia}" />

    <link name="tip">
      <visual>
      <geometry>
          <mesh filename="${mesh_file_tip}"
            scale="${mesh_scale} ${mesh_scale} ${mesh_scale}"/>
        </geometry>
        <origin rpy="0 0 0" xyz="0 0 0"/>
      </visual>
      <collision>
        <geometry>
          <mesh filename="${s_mesh_file_tip}"
            scale="${mesh_scale} ${mesh_scale} ${mesh_scale}"/>
          </geometry>
        <origin rpy="0 0 0" xyz="0 0 0"/>
      </collision>
      <inertial>
        <mass value="${tip_mass}"/>
        <inertia ixx="${tip_ixx}" ixy="${tip_ixy}" ixz="${tip_ixz}" iyy="${tip_iyy}" iyz="${tip_iyz}" izz="${tip_izz}" />
      </inertial>
    </link>




</robot>
