<?xml version="1.0"?>
<robot name="arm" xmlns:xacro="http://ros.org/wiki/xacro">



  <!-- Material and Colors-->
  <material name="black">
    <color rgba="${0/255} ${0/255} ${0/255} 1.0"/>
  </material>
  <material name="dark_grey">
    <color rgba="${105/255} {105/255} ${105/255} 1.0"/>
  </material>
  <material name="grey">
    <color rgba="${128/255} ${128/255} ${128/255} 1.0"/>
  </material>
  <material name="light_grey">
    <color rgba="${221/255} ${221/255} ${221/255} 1"/>
  </material>
  <material name="white">
    <color rgba="${255/255} ${255/255} ${255/255} 1.0"/>
  </material>
  <material name="red">
    <color rgba="${255/255} ${0/255} ${0/255} 1.0"/>
  </material>


    <!-- General Variables-->
    <xacro:property name="pi" value="3.1415269" />

    <!-- Mesh files-->
    <xacro:property name="mesh_file_baseplate" value="package://mav_arm_force_controlled/meshes/baseplate.stl" />
    <xacro:property name="mesh_file_dyamixel" value="package://mav_arm_force_controlled/meshes/dynamixel.stl" />
    <xacro:property name="mesh_file_connecting" value="package://mav_arm_force_controlled/meshes/connecting.stl" />
    <xacro:property name="mesh_file_hebi" value="package://mav_arm_force_controlled/meshes/hebi.stl" />
    <xacro:property name="mesh_file_hebitotube2" value="package://mav_arm_force_controlled/meshes/hebitotube2.stl" />
      <!--
    <xacro:property name="mesh_file_hebhebii" value="package://mav_arm_force_controlled/meshes/hebi.stl" />
    <xacro:property name="mesh_file_hebi" value="package://mav_arm_force_controlled/meshes/hebi.stl" />
-->
    <!-- Mesh files are in mm. All mesh files are scaled by the factor 10000-->
    <xacro:property name="mesh_scale" value="0.001" />

    <!-- First element, Base Plate-->


    <xacro:property name="baseplate_mass" value="0.040063354" />

    <xacro:property name="baseplate_cog_x" value="0.025202079" />
    <xacro:property name="baseplate_cog_y" value="0" />
    <xacro:property name="baseplate_cog_z" value="0.0025" />

    <xacro:property name="baseplate_ixx" value="0.000063973" />
    <xacro:property name="baseplate_ixy" value="0" />
    <xacro:property name="baseplate_ixz" value="0.000005877" />
    <xacro:property name="baseplate_iyy" value="0.000151767" />
    <xacro:property name="baseplate_iyz" value="0" />
    <xacro:property name="baseplate_izz" value="0.000214186" />



  <link name="baseplate">
    <visual>
      <geometry>
          <mesh filename="${mesh_file_baseplate}"
                scale="${mesh_scale} ${mesh_scale} ${mesh_scale}"/>
        </geometry>
      <origin rpy="0 0 0" xyz="0 0 0"/>
      <!--<origin rpy="0 0 0" xyz="${Baseplate_cog_x} ${Baseplate_cog_y} ${Baseplate_cog_z}"/>-->
      <material name="black"/>
    </visual>
    <collision>
      <geometry>
      </geometry>
    </collision>
    <inertia>
      <mass value="${baseplate_mass}"/>
      <inertia ixx="${baseplate_ixx}" ixy="${baseplate_ixy}" ixz="${baseplate_ixz}" iyy="${baseplate_iyy}" iyz="${baseplate_iyz}" izz="${baseplate_izz}" />
    </inertia>
  </link>

  <joint name="baseplate_to_actuator3" type="fixed">
    <parent link="baseplate"/>
    <child link="actuator3"/>
    <origin rpy="0 0 ${-pi/2}" xyz="${0.0425+0.0055} 0 ${.005+0.017}"/>
  </joint>



  <xacro:property name="dynamixel_mass" value="0.126" />

  <xacro:property name="dynamixel_cog_x" value="0.000000008" />
  <xacro:property name="dynamixel_cog_y" value="-0.01519089" />
  <xacro:property name="dynamixel_cog_z" value="0.000362847" />

  <xacro:property name="dynamixel_ixx" value="0.000129338" />
  <xacro:property name="dynamixel_ixy" value="0" />
  <xacro:property name="dynamixel_ixz" value="0" />
  <xacro:property name="dynamixel_iyy" value="0.000047045" />
  <xacro:property name="dynamixel_iyz" value="0.0000014" />
  <xacro:property name="dynamixel_izz" value="0.000115625" />


  <link name="actuator3">
    <visual>
      <geometry>
          <mesh filename="${mesh_file_dyamixel}"
                scale="${mesh_scale} ${mesh_scale} ${mesh_scale}"/>
        </geometry>
        <origin rpy="0 0 0" xyz="0 0 0"/>
        <material name="black"/>
    </visual>
    <collision>
      <geometry>
      </geometry>
    </collision>
    <inertia>
      <origin xyz="dynamixel_cog_x dynamixel_cog_y dynamixel_cog_z"/>
      <mass value="${dynamixel_mass}"/>
      <inertia ixx="${dynamixel_ixy}" ixy="${dynamixel_ixy}" ixz="${dynamixel_ixz}" iyy="${dynamixel_iyy}" iyz="${dynamixel_iyz}" izz="${dynamixel_izz}" />
    </inertia>
  </link>


  <joint name="actuator3_to_connectingplate" type="continuous">
    <axis rpy="0 0 0" xyz="0 0 1"/>
    <parent link="actuator3"/>
    <child link="connectingbox"/>
    <origin rpy="0 0 ${pi}" xyz="0 0 ${0.0235+0.0035}"/>
  </joint>

  <xacro:property name="connectionmx64hebi_mass" value=" 0.402140403" />

  <xacro:property name="connectionmx64hebi_cog_x" value="0.000000171" />
  <xacro:property name="connectionmx64hebi_cog_y" value="0.000278026" />
  <xacro:property name="connectionmx64hebi_cog_z" value="0.038471524" />

  <xacro:property name="connectionmx64hebi_ixx" value="0.001105121" />
  <xacro:property name="connectionmx64hebi_ixy" value="0.000000016" />
  <xacro:property name="connectionmx64hebi_ixz" value="0" />
  <xacro:property name="connectionmx64hebi_iyy" value="0.001002814" />
  <xacro:property name="connectionmx64hebi_iyz" value="0.000007088" />
  <xacro:property name="connectionmx64hebi_izz" value="0.000170487" />


  <link name="connectingbox">
    <visual>
      <geometry>
        <mesh filename="${mesh_file_connecting}"
              scale="${mesh_scale} ${mesh_scale} ${mesh_scale}"/>
      </geometry>
      <origin rpy="0 0 0" xyz="0 0 0"/>
      <material name="black"/>
    </visual>
    <collision>
      <geometry>
      </geometry>
    </collision>
    <inertia>
      <mass value="0.01"/>
      <inertia ixx="${connectionmx64hebi_ixx}" ixy="${connectionmx64hebi_ixy}" ixz="${connectionmx64hebi_ixz}" iyy="${connectionmx64hebi_iyy}" iyz="${connectionmx64hebi_iyz}" izz="${connectionmx64hebi_izz}" />
    </inertia>
  </link>

  <joint name="connectingbox_to_actuator2" type="fixed">
    <parent link="connectingbox"/>
    <child link="actuator2"/>
    <origin rpy="${pi/2} ${0} ${pi/2}"  xyz="${0.025} ${0} ${0.001+0.055}"/>
  </joint>

  <link name="actuator2">
    <visual>
      <geometry>
        <mesh filename="${mesh_file_hebi}"
              scale="${mesh_scale} ${mesh_scale} ${mesh_scale}"/>
      </geometry>
      <origin rpy="0 0 0" xyz="0 0 0"/>
      <material name="red"/>
    </visual>
    <collision>
      <geometry>
        <box size="0.031 0.11 0.073"/>
      </geometry>
    </collision>
    <inertia>
      <mass value="0.34"/>
      <inertia ixx="0.001" ixy="0" ixz="0" iyy="0.001" iyz="0" izz="0.001" />
    </inertia>
  </link>


  <joint name="actuator2_to_clamp3" type="continuous">
    <axis rpy="0 0 0" xyz="0 0 1"/> />
    <parent link="actuator2"/>
    <child link="clamp3"/>
    <origin rpy="0 0 0" xyz="${0} 0 ${0.01605}"/>
  </joint>

  <link name="clamp3">
    <visual>
      <geometry>
        <mesh filename="${mesh_file_hebitotube2}"
              scale="${mesh_scale} ${mesh_scale} ${mesh_scale}"/>
      </geometry>
      <origin rpy="0 0 0" xyz="0 0 0"/>
      <material name="black"/>
    </visual>
    <collision>
      <geometry>
        <sphere radius="0.02"/>
      </geometry>
    </collision>
    <inertia>
      <mass value="0.01"/>
      <inertia ixx="0.000917686" ixy="0.000000017" ixz="0.000000018" iyy="0.000928465" iyz="0.000093232" izz="0.000074342" />
    </inertia>
  </link>



    <!--

  <joint name="clamp3_to_tube2" type="fixed">
    <parent link="clamp3"/>
    <child link="tube2"/>
    <origin xyz="-0.031 0 0"/>
  </joint>

  <link name="tube2">
    <visual>
      <geometry>
        <cylinder length="0.6" radius="0.01"/>
      </geometry>
      <origin rpy="1.570796 0 0" xyz="-0.01 0.3 0"/>
      <material name="light_grey"/>
    </visual>
    <collision>
      <geometry>
        <cylinder length="0.6" radius="0.01"/>
      </geometry>
    </collision>
    <inertia>
      <mass value="0.01"/>
      <inertia ixx="0.0012" ixy="0" ixz="0" iyy="0" iyz="0" izz="0.0012" />
    </inertia>
  </link>


    <joint name="tube2_to_clamp2" type="fixed">
      <parent link="tube2"/>
      <child link="clamp2"/>
      <origin rpy="0 0 0" xyz="0 0.3 0"/>
    </joint>


    <link name="clamp2">
      <visual>
        <geometry>
          <sphere radius="0.02"/>
        </geometry>
        <origin rpy="1.570796 0 0" xyz="-0.01 0.3 0"/>
        <material name="black"/>
      </visual>
      <collision>
        <geometry>
          <sphere radius="0.02"/>
        </geometry>
      </collision>
      <inertia>
        <mass value="0.01"/>
        <inertia ixx="0.0012" ixy="0" ixz="0" iyy="0" iyz="0" izz="0.0012" />
      </inertia>
    </link>

      <joint name="clamp2_to_actuator1" type="fixed">
        <parent link="clamp2"/>
        <child link="actuator1"/>
        <origin rpy="0 1.5707963 0" xyz="0 0.3 0"/>
      </joint>



  <link name="actuator1">
    <visual>
      <geometry>
          <mesh filename="${mesh_file_actuator1}"
            scale="${mesh_scale} ${mesh_scale} ${mesh_scale}"/>
        </geometry>
      <origin rpy="0 0 0" xyz="0 -0.0305 0.0205"/>
      <material name="black"/>
    </visual>
    <collision>
      <geometry>
        <box size="0.04 0.061 0.041"/>
      </geometry>
    </collision>
    <inertia>
      <mass value="0.22"/>
      <inertia ixx="0.00003691125" ixy="0" ixz="0" iyy="0.00005986125" iyz="0" izz="0.0000607725" />
    </inertia>
  </link>


  <joint name="actuator1_to_clamp1" type="continuous">
    <axis rpy="0 0 0" xyz="0 0 1"/>
    <parent link="actuator1"/>
    <child link="clamp1"/>
    <origin xyz="0 -0.013 0.041"/>
  </joint>

  <link name="clamp1">
    <visual>
      <geometry>
        <sphere radius="0.02"/>
      </geometry>
      <origin rpy="0 0 0" xyz="0 -0.0305 0.0205"/>
      <material name="black"/>
    </visual>
    <collision>
      <geometry>
        <sphere radius="0.02"/>
      </geometry>
    </collision>
    <inertia>
      <mass value="0.22"/>
      <inertia ixx="0.00003691125" ixy="0" ixz="0" iyy="0.00005986125" iyz="0" izz="0.0000607725" />
    </inertia>
  </link>


  <joint name="clamp1_to_tube1" type="fixed">
    <parent link="clamp1"/>
    <child link="tube1"/>
    <origin xyz="0 0 0"/>
  </joint>


    <link name="tube1">
      <visual>
        <geometry>
          <cylinder length="0.4" radius="0.007"/>
        </geometry>
        <origin rpy="1.570796 0 0" xyz="0 0.2 0.007"/>
        <material name="light_grey"/>
      </visual>
      <collision>
        <geometry>
          <cylinder length="0.4" radius="0.007"/>
        </geometry>
      </collision>
      <inertia>
        <mass value="0.01"/>
        <inertia ixx="0.0012" ixy="0" ixz="0" iyy="0" iyz="0" izz="0.0012" />
      </inertia>
    </link>

    <joint name="tube1_to_tip" type="fixed">
      <parent link="tube1"/>
      <child link="tip"/>
      <origin xyz="0 0.4 0.007"/>
    </joint>

    <link name="tip">
      <visual>
      <geometry>
          <mesh filename="${mesh_file_tip}"
            scale="${mesh_scale} ${mesh_scale} ${mesh_scale}"/>
        </geometry>
        <origin rpy="${-pi/2} 0 0" xyz="0 0 0"/>
        <material name="white"/>
      </visual>
      <collision>
        <geometry>
          <sphere radius="0.014"/>
        </geometry>
      </collision>
      <inertia>
        <mass value="0.01"/>
        <inertia ixx="0.00028" ixy="0" ixz="0" iyy="0.00028" iyz="0" izz="0.00028" />
      </inertia>
    </link>
-->
</robot>
